2024-07-30 22:53:38 [INFO] Question: how many columns are in the dataset?
2024-07-30 22:53:38 [INFO] Running PandasAI with local LLM...
2024-07-30 22:53:38 [INFO] Prompt ID: 8df691ad-256b-4f92-bbc5-515f1a9d40f1
2024-07-30 22:53:38 [INFO] Executing Pipeline: GenerateChatPipeline
2024-07-30 22:53:38 [INFO] Executing Step 0: ValidatePipelineInput
2024-07-30 22:53:38 [INFO] Executing Step 1: CacheLookup
2024-07-30 22:53:38 [INFO] Executing Step 2: PromptGeneration
2024-07-30 22:53:38 [INFO] Using prompt: <dataframe>
dfs[0]:5x3
NUMBER,LETTER,MONTH
1,D,January
5,A,May
4,E,February
</dataframe>




Update this initial code:
```python
# TODO: import the required dependencies
import pandas as pd

# Write code here

# Declare result var: 
type (possible values "string", "number", "dataframe", "plot"). Examples: { "type": "string", "value": f"The highest salary is {highest_salary}." } or { "type": "number", "value": 125 } or { "type": "dataframe", "value": pd.DataFrame({...}) } or { "type": "plot", "value": "temp_chart.png" }

```



### QUERY
 how many columns are in the dataset?

Variable `dfs: list[pd.DataFrame]` is already declared.

At the end, declare "result" variable as a dictionary of type and value.

If you are asked to plot a chart, use "matplotlib" for charts, save as png.


Generate python code and return full updated code:
2024-07-30 22:53:38 [INFO] Executing Step 3: CodeGenerator
2024-07-30 22:54:13 [INFO] HTTP Request: POST http://localhost:11434/v1/chat/completions "HTTP/1.1 200 OK"
2024-07-30 22:54:13 [INFO] Prompt used:
            <dataframe>
dfs[0]:5x3
NUMBER,LETTER,MONTH
1,D,January
5,A,May
4,E,February
</dataframe>




Update this initial code:
```python
# TODO: import the required dependencies
import pandas as pd

# Write code here

# Declare result var: 
type (possible values "string", "number", "dataframe", "plot"). Examples: { "type": "string", "value": f"The highest salary is {highest_salary}." } or { "type": "number", "value": 125 } or { "type": "dataframe", "value": pd.DataFrame({...}) } or { "type": "plot", "value": "temp_chart.png" }

```



### QUERY
 how many columns are in the dataset?

Variable `dfs: list[pd.DataFrame]` is already declared.

At the end, declare "result" variable as a dictionary of type and value.

If you are asked to plot a chart, use "matplotlib" for charts, save as png.


Generate python code and return full updated code:
            
2024-07-30 22:54:13 [INFO] Code generated:
            ```
            # Import the required libraries
import pandas as pd
import matplotlib.pyplot as plt

# Initialize an empty list to store the data frames
dfs = []

# Add columns with unique values in each row to the dfs list
for _, row in df.iterrows():
    new_df = {
        "NUMBER": str(row[0]),  # Extracting the first element of the rows and converting it into string type
        "LETTER": str(row[1]),   # Extracting the second element of the rows and converting it into string type
        "MONTH": str(row[2])    # Extracting the third element of the rows and converting it into string type
    }
    dfs.append(pd.DataFrame(new_df))

# Join all data frames in the dfs list
result = pd.concat(dfs, ignore_index=True)

print("The dataset has", len(result.columns), "columns.")

# Define a function to plot the number of unique values per column
def plot_unique_values(column):
    plt.figure(figsize=(10, 5))
    unique_counts = result[column].unique().shape[0]
    plt.bar(unique_counts * [column], range(unique_counts), color="blue")
    plt.xlabel("Column Name")
    plt.ylabel("Number of Unique Values")
    plt.title(f"{result[column].nunique()}-unique values in column {column}")
    return plt.gcf()

# Create the plot for each unique value
for col_name, df in dfs.items():
    plot_unique_values(col_name)

plt.tight_layout()
plt.show()

print(f"The chart is saved as temp_chart.png.")
            ```
            
2024-07-30 22:54:13 [INFO] Executing Step 4: CachePopulation
2024-07-30 22:54:13 [INFO] Executing Step 5: CodeCleaning
2024-07-30 22:54:13 [INFO] Saving charts to /home/caio/workspace/genai/exports/charts/temp_chart.png
2024-07-30 22:54:13 [INFO] 
Code running:
```
for _, row in df.iterrows():
    new_df = {'NUMBER': str(row[0]), 'LETTER': str(row[1]), 'MONTH': str(row[2])}
    dfs.append(pd.DataFrame(new_df))
result = pd.concat(dfs, ignore_index=True)
print('The dataset has', len(result.columns), 'columns.')


def plot_unique_values(column):
    plt.figure(figsize=(10, 5))
    unique_counts = result[column].unique().shape[0]
    plt.bar(unique_counts * [column], range(unique_counts), color='blue')
    plt.xlabel('Column Name')
    plt.ylabel('Number of Unique Values')
    plt.title(f'{result[column].nunique()}-unique values in column {column}')
    return plt.gcf()


for col_name, df in dfs.items():
    plot_unique_values(col_name)
plt.tight_layout()
plt.show()
print(f'The chart is saved as /home/caio/workspace/genai/exports/charts/temp_chart.png.')
        ```
2024-07-30 22:54:13 [INFO] Executing Step 6: CodeExecution
2024-07-30 22:54:13 [ERROR] Failed with error: Traceback (most recent call last):
  File "/home/caio/workspace/genai/.genai/lib/python3.10/site-packages/pandasai/pipelines/chat/code_execution.py", line 85, in execute
    result = self.execute_code(code_to_run, code_context)
  File "/home/caio/workspace/genai/.genai/lib/python3.10/site-packages/pandasai/pipelines/chat/code_execution.py", line 171, in execute_code
    exec(code, environment)
  File "<string>", line 3, in <module>
  File "/home/caio/workspace/genai/.genai/lib/python3.10/site-packages/pandas/core/frame.py", line 664, in __init__
    mgr = dict_to_mgr(data, index, columns, dtype=dtype, copy=copy, typ=manager)
  File "/home/caio/workspace/genai/.genai/lib/python3.10/site-packages/pandas/core/internals/construction.py", line 493, in dict_to_mgr
    return arrays_to_mgr(arrays, columns, index, dtype=dtype, typ=typ, consolidate=copy)
  File "/home/caio/workspace/genai/.genai/lib/python3.10/site-packages/pandas/core/internals/construction.py", line 118, in arrays_to_mgr
    index = _extract_index(arrays)
  File "/home/caio/workspace/genai/.genai/lib/python3.10/site-packages/pandas/core/internals/construction.py", line 656, in _extract_index
    raise ValueError("If using all scalar values, you must pass an index")
ValueError: If using all scalar values, you must pass an index

2024-07-30 22:54:13 [WARNING] Failed to execute code retrying with a correction framework [retry number: 1]
2024-07-30 22:54:13 [INFO] Executing Pipeline: ErrorCorrectionPipeline
2024-07-30 22:54:13 [INFO] Executing Step 0: ErrorPromptGeneration
2024-07-30 22:54:13 [INFO] Using prompt: <dataframe>
dfs[0]:5x3
NUMBER,LETTER,MONTH
1,D,January
5,A,May
4,E,February
</dataframe>


The user asked the following question:
### QUERY
 how many columns are in the dataset?

You generated this python code:
for _, row in df.iterrows():
    new_df = {'NUMBER': str(row[0]), 'LETTER': str(row[1]), 'MONTH': str(row[2])}
    dfs.append(pd.DataFrame(new_df))
result = pd.concat(dfs, ignore_index=True)
print('The dataset has', len(result.columns), 'columns.')


def plot_unique_values(column):
    plt.figure(figsize=(10, 5))
    unique_counts = result[column].unique().shape[0]
    plt.bar(unique_counts * [column], range(unique_counts), color='blue')
    plt.xlabel('Column Name')
    plt.ylabel('Number of Unique Values')
    plt.title(f'{result[column].nunique()}-unique values in column {column}')
    return plt.gcf()


for col_name, df in dfs.items():
    plot_unique_values(col_name)
plt.tight_layout()
plt.show()
print(f'The chart is saved as /home/caio/workspace/genai/exports/charts/temp_chart.png.')

It fails with the following error:
Traceback (most recent call last):
  File "/home/caio/workspace/genai/.genai/lib/python3.10/site-packages/pandasai/pipelines/chat/code_execution.py", line 85, in execute
    result = self.execute_code(code_to_run, code_context)
  File "/home/caio/workspace/genai/.genai/lib/python3.10/site-packages/pandasai/pipelines/chat/code_execution.py", line 171, in execute_code
    exec(code, environment)
  File "<string>", line 3, in <module>
  File "/home/caio/workspace/genai/.genai/lib/python3.10/site-packages/pandas/core/frame.py", line 664, in __init__
    mgr = dict_to_mgr(data, index, columns, dtype=dtype, copy=copy, typ=manager)
  File "/home/caio/workspace/genai/.genai/lib/python3.10/site-packages/pandas/core/internals/construction.py", line 493, in dict_to_mgr
    return arrays_to_mgr(arrays, columns, index, dtype=dtype, typ=typ, consolidate=copy)
  File "/home/caio/workspace/genai/.genai/lib/python3.10/site-packages/pandas/core/internals/construction.py", line 118, in arrays_to_mgr
    index = _extract_index(arrays)
  File "/home/caio/workspace/genai/.genai/lib/python3.10/site-packages/pandas/core/internals/construction.py", line 656, in _extract_index
    raise ValueError("If using all scalar values, you must pass an index")
ValueError: If using all scalar values, you must pass an index


Fix the python code above and return the new python code:
2024-07-30 22:54:13 [INFO] Executing Step 1: CodeGenerator
2024-07-30 22:54:32 [INFO] HTTP Request: POST http://localhost:11434/v1/chat/completions "HTTP/1.1 200 OK"
2024-07-30 22:54:32 [INFO] Prompt used:
            <dataframe>
dfs[0]:5x3
NUMBER,LETTER,MONTH
1,D,January
5,A,May
4,E,February
</dataframe>


The user asked the following question:
### QUERY
 how many columns are in the dataset?

You generated this python code:
for _, row in df.iterrows():
    new_df = {'NUMBER': str(row[0]), 'LETTER': str(row[1]), 'MONTH': str(row[2])}
    dfs.append(pd.DataFrame(new_df))
result = pd.concat(dfs, ignore_index=True)
print('The dataset has', len(result.columns), 'columns.')


def plot_unique_values(column):
    plt.figure(figsize=(10, 5))
    unique_counts = result[column].unique().shape[0]
    plt.bar(unique_counts * [column], range(unique_counts), color='blue')
    plt.xlabel('Column Name')
    plt.ylabel('Number of Unique Values')
    plt.title(f'{result[column].nunique()}-unique values in column {column}')
    return plt.gcf()


for col_name, df in dfs.items():
    plot_unique_values(col_name)
plt.tight_layout()
plt.show()
print(f'The chart is saved as /home/caio/workspace/genai/exports/charts/temp_chart.png.')

It fails with the following error:
Traceback (most recent call last):
  File "/home/caio/workspace/genai/.genai/lib/python3.10/site-packages/pandasai/pipelines/chat/code_execution.py", line 85, in execute
    result = self.execute_code(code_to_run, code_context)
  File "/home/caio/workspace/genai/.genai/lib/python3.10/site-packages/pandasai/pipelines/chat/code_execution.py", line 171, in execute_code
    exec(code, environment)
  File "<string>", line 3, in <module>
  File "/home/caio/workspace/genai/.genai/lib/python3.10/site-packages/pandas/core/frame.py", line 664, in __init__
    mgr = dict_to_mgr(data, index, columns, dtype=dtype, copy=copy, typ=manager)
  File "/home/caio/workspace/genai/.genai/lib/python3.10/site-packages/pandas/core/internals/construction.py", line 493, in dict_to_mgr
    return arrays_to_mgr(arrays, columns, index, dtype=dtype, typ=typ, consolidate=copy)
  File "/home/caio/workspace/genai/.genai/lib/python3.10/site-packages/pandas/core/internals/construction.py", line 118, in arrays_to_mgr
    index = _extract_index(arrays)
  File "/home/caio/workspace/genai/.genai/lib/python3.10/site-packages/pandas/core/internals/construction.py", line 656, in _extract_index
    raise ValueError("If using all scalar values, you must pass an index")
ValueError: If using all scalar values, you must pass an index


Fix the python code above and return the new python code:
            
2024-07-30 22:54:32 [INFO] Code generated:
            ```
            df['NUMBER'] = df['NUMBER'].astype(str)
result = pd.concat([df['NUMBER'], df['LETTER']], ignore_index=True)

plot_unique_values(df['MONTH'])
plt.show()
print(f'The chart is saved as /home/caio/workspace/genai/exports/charts/temp_chart.png.')
            ```
            
2024-07-30 22:54:32 [INFO] Executing Step 2: CodeCleaning
2024-07-30 22:54:32 [INFO] Saving charts to /home/caio/workspace/genai/exports/charts/temp_chart.png
2024-07-30 22:54:32 [INFO] 
Code running:
```
df['NUMBER'] = df['NUMBER'].astype(str)
result = pd.concat([df['NUMBER'], df['LETTER']], ignore_index=True)
plot_unique_values(df['MONTH'])
plt.show()
print(f'The chart is saved as /home/caio/workspace/genai/exports/charts//home/caio/workspace/genai/exports/charts/temp_chart.png.')
        ```
2024-07-30 22:54:32 [ERROR] Failed with error: Traceback (most recent call last):
  File "/home/caio/workspace/genai/.genai/lib/python3.10/site-packages/pandasai/pipelines/chat/code_execution.py", line 85, in execute
    result = self.execute_code(code_to_run, code_context)
  File "/home/caio/workspace/genai/.genai/lib/python3.10/site-packages/pandasai/pipelines/chat/code_execution.py", line 171, in execute_code
    exec(code, environment)
  File "<string>", line 1, in <module>
TypeError: 'NoneType' object is not subscriptable

2024-07-30 22:54:32 [WARNING] Failed to execute code retrying with a correction framework [retry number: 2]
2024-07-30 22:54:32 [INFO] Executing Pipeline: ErrorCorrectionPipeline
2024-07-30 22:54:32 [INFO] Executing Step 0: ErrorPromptGeneration
2024-07-30 22:54:32 [INFO] Using prompt: <dataframe>
dfs[0]:5x3
NUMBER,LETTER,MONTH
1,D,January
5,A,May
4,E,February
</dataframe>


The user asked the following question:
### QUERY
 how many columns are in the dataset?

You generated this python code:
df['NUMBER'] = df['NUMBER'].astype(str)
result = pd.concat([df['NUMBER'], df['LETTER']], ignore_index=True)
plot_unique_values(df['MONTH'])
plt.show()
print(f'The chart is saved as /home/caio/workspace/genai/exports/charts//home/caio/workspace/genai/exports/charts/temp_chart.png.')

It fails with the following error:
Traceback (most recent call last):
  File "/home/caio/workspace/genai/.genai/lib/python3.10/site-packages/pandasai/pipelines/chat/code_execution.py", line 85, in execute
    result = self.execute_code(code_to_run, code_context)
  File "/home/caio/workspace/genai/.genai/lib/python3.10/site-packages/pandasai/pipelines/chat/code_execution.py", line 171, in execute_code
    exec(code, environment)
  File "<string>", line 1, in <module>
TypeError: 'NoneType' object is not subscriptable


Fix the python code above and return the new python code:
2024-07-30 22:54:32 [INFO] Executing Step 1: CodeGenerator
2024-07-30 22:54:48 [INFO] HTTP Request: POST http://localhost:11434/v1/chat/completions "HTTP/1.1 200 OK"
2024-07-30 22:54:48 [INFO] Prompt used:
            <dataframe>
dfs[0]:5x3
NUMBER,LETTER,MONTH
1,D,January
5,A,May
4,E,February
</dataframe>


The user asked the following question:
### QUERY
 how many columns are in the dataset?

You generated this python code:
df['NUMBER'] = df['NUMBER'].astype(str)
result = pd.concat([df['NUMBER'], df['LETTER']], ignore_index=True)
plot_unique_values(df['MONTH'])
plt.show()
print(f'The chart is saved as /home/caio/workspace/genai/exports/charts//home/caio/workspace/genai/exports/charts/temp_chart.png.')

It fails with the following error:
Traceback (most recent call last):
  File "/home/caio/workspace/genai/.genai/lib/python3.10/site-packages/pandasai/pipelines/chat/code_execution.py", line 85, in execute
    result = self.execute_code(code_to_run, code_context)
  File "/home/caio/workspace/genai/.genai/lib/python3.10/site-packages/pandasai/pipelines/chat/code_execution.py", line 171, in execute_code
    exec(code, environment)
  File "<string>", line 1, in <module>
TypeError: 'NoneType' object is not subscriptable


Fix the python code above and return the new python code:
            
2024-07-30 22:54:48 [INFO] Code generated:
            ```
            import pandas as pd
from matplotlib.pyplot import figure

# Load the dataset
df = pd.read_csv('path/to/your/dataset.csv')

# Convert the 'NUMBER' column to string and set it as the first column in the DataFrame
df['NUMBER'] = df['NUMBER'].astype(str)
result = pd.concat([df['NUMBER'], df['LETTER']], ignore_index=True)

# Plot unique values of 'MONTH'
plot_unique_values(df['MONTH'])
plt.show()

# Save the chart to a file
print(f'The chart is saved as /home/caio/workspace/genai/exports/charts/temp_chart.png.')
            ```
            
2024-07-30 22:54:48 [INFO] Executing Step 2: CodeCleaning
2024-07-30 22:54:48 [INFO] Saving charts to /home/caio/workspace/genai/exports/charts/temp_chart.png
2024-07-30 22:54:48 [INFO] 
Code running:
```
df = pd.read_csv('path/to/your/dataset.csv')
df['NUMBER'] = df['NUMBER'].astype(str)
result = pd.concat([df['NUMBER'], df['LETTER']], ignore_index=True)
plot_unique_values(df['MONTH'])
plt.show()
print(f'The chart is saved as /home/caio/workspace/genai/exports/charts//home/caio/workspace/genai/exports/charts/temp_chart.png.')
        ```
2024-07-30 22:54:48 [ERROR] Failed with error: Traceback (most recent call last):
  File "/home/caio/workspace/genai/.genai/lib/python3.10/site-packages/pandasai/pipelines/chat/code_execution.py", line 85, in execute
    result = self.execute_code(code_to_run, code_context)
  File "/home/caio/workspace/genai/.genai/lib/python3.10/site-packages/pandasai/pipelines/chat/code_execution.py", line 171, in execute_code
    exec(code, environment)
  File "<string>", line 1, in <module>
  File "/home/caio/workspace/genai/.genai/lib/python3.10/site-packages/pandas/util/_decorators.py", line 211, in wrapper
    return func(*args, **kwargs)
  File "/home/caio/workspace/genai/.genai/lib/python3.10/site-packages/pandas/util/_decorators.py", line 331, in wrapper
    return func(*args, **kwargs)
  File "/home/caio/workspace/genai/.genai/lib/python3.10/site-packages/pandas/io/parsers/readers.py", line 950, in read_csv
    return _read(filepath_or_buffer, kwds)
  File "/home/caio/workspace/genai/.genai/lib/python3.10/site-packages/pandas/io/parsers/readers.py", line 605, in _read
    parser = TextFileReader(filepath_or_buffer, **kwds)
  File "/home/caio/workspace/genai/.genai/lib/python3.10/site-packages/pandas/io/parsers/readers.py", line 1442, in __init__
    self._engine = self._make_engine(f, self.engine)
  File "/home/caio/workspace/genai/.genai/lib/python3.10/site-packages/pandas/io/parsers/readers.py", line 1735, in _make_engine
    self.handles = get_handle(
  File "/home/caio/workspace/genai/.genai/lib/python3.10/site-packages/pandas/io/common.py", line 856, in get_handle
    handle = open(
FileNotFoundError: [Errno 2] No such file or directory: 'path/to/your/dataset.csv'

2024-07-30 22:54:48 [WARNING] Failed to execute code retrying with a correction framework [retry number: 3]
2024-07-30 22:54:48 [INFO] Executing Pipeline: ErrorCorrectionPipeline
2024-07-30 22:54:48 [INFO] Executing Step 0: ErrorPromptGeneration
2024-07-30 22:54:48 [INFO] Using prompt: <dataframe>
dfs[0]:5x3
NUMBER,LETTER,MONTH
1,D,January
5,A,May
4,E,February
</dataframe>


The user asked the following question:
### QUERY
 how many columns are in the dataset?

You generated this python code:
df = pd.read_csv('path/to/your/dataset.csv')
df['NUMBER'] = df['NUMBER'].astype(str)
result = pd.concat([df['NUMBER'], df['LETTER']], ignore_index=True)
plot_unique_values(df['MONTH'])
plt.show()
print(f'The chart is saved as /home/caio/workspace/genai/exports/charts//home/caio/workspace/genai/exports/charts/temp_chart.png.')

It fails with the following error:
Traceback (most recent call last):
  File "/home/caio/workspace/genai/.genai/lib/python3.10/site-packages/pandasai/pipelines/chat/code_execution.py", line 85, in execute
    result = self.execute_code(code_to_run, code_context)
  File "/home/caio/workspace/genai/.genai/lib/python3.10/site-packages/pandasai/pipelines/chat/code_execution.py", line 171, in execute_code
    exec(code, environment)
  File "<string>", line 1, in <module>
  File "/home/caio/workspace/genai/.genai/lib/python3.10/site-packages/pandas/util/_decorators.py", line 211, in wrapper
    return func(*args, **kwargs)
  File "/home/caio/workspace/genai/.genai/lib/python3.10/site-packages/pandas/util/_decorators.py", line 331, in wrapper
    return func(*args, **kwargs)
  File "/home/caio/workspace/genai/.genai/lib/python3.10/site-packages/pandas/io/parsers/readers.py", line 950, in read_csv
    return _read(filepath_or_buffer, kwds)
  File "/home/caio/workspace/genai/.genai/lib/python3.10/site-packages/pandas/io/parsers/readers.py", line 605, in _read
    parser = TextFileReader(filepath_or_buffer, **kwds)
  File "/home/caio/workspace/genai/.genai/lib/python3.10/site-packages/pandas/io/parsers/readers.py", line 1442, in __init__
    self._engine = self._make_engine(f, self.engine)
  File "/home/caio/workspace/genai/.genai/lib/python3.10/site-packages/pandas/io/parsers/readers.py", line 1735, in _make_engine
    self.handles = get_handle(
  File "/home/caio/workspace/genai/.genai/lib/python3.10/site-packages/pandas/io/common.py", line 856, in get_handle
    handle = open(
FileNotFoundError: [Errno 2] No such file or directory: 'path/to/your/dataset.csv'


Fix the python code above and return the new python code:
2024-07-30 22:54:48 [INFO] Executing Step 1: CodeGenerator
2024-07-30 22:57:35 [INFO] Question: how many columns are in the dataset?
2024-07-30 22:57:35 [INFO] Running PandasAI with local LLM...
2024-07-30 22:57:35 [INFO] Prompt ID: 1a3c5398-cd8a-468e-9e0c-72410833ed64
2024-07-30 22:57:35 [INFO] Executing Pipeline: GenerateChatPipeline
2024-07-30 22:57:35 [INFO] Executing Step 0: ValidatePipelineInput
2024-07-30 22:57:35 [INFO] Executing Step 1: CacheLookup
2024-07-30 22:57:35 [INFO] Using cached response
2024-07-30 22:57:35 [INFO] Executing Step 2: PromptGeneration
2024-07-30 22:57:35 [INFO] Executing Step 2: Skipping...
2024-07-30 22:57:35 [INFO] Executing Step 3: CodeGenerator
2024-07-30 22:57:35 [INFO] Executing Step 3: Skipping...
2024-07-30 22:57:35 [INFO] Executing Step 4: CachePopulation
2024-07-30 22:57:35 [INFO] Executing Step 4: Skipping...
2024-07-30 22:57:35 [INFO] Executing Step 5: CodeCleaning
2024-07-30 22:57:35 [INFO] Saving charts to /home/caio/workspace/genai/exports/charts/temp_chart.png
2024-07-30 22:57:35 [INFO] 
Code running:
```
for _, row in df.iterrows():
    new_df = {'NUMBER': str(row[0]), 'LETTER': str(row[1]), 'MONTH': str(row[2])}
    dfs.append(pd.DataFrame(new_df))
result = pd.concat(dfs, ignore_index=True)
print('The dataset has', len(result.columns), 'columns.')


def plot_unique_values(column):
    plt.figure(figsize=(10, 5))
    unique_counts = result[column].unique().shape[0]
    plt.bar(unique_counts * [column], range(unique_counts), color='blue')
    plt.xlabel('Column Name')
    plt.ylabel('Number of Unique Values')
    plt.title(f'{result[column].nunique()}-unique values in column {column}')
    return plt.gcf()


for col_name, df in dfs.items():
    plot_unique_values(col_name)
plt.tight_layout()
plt.show()
print(f'The chart is saved as /home/caio/workspace/genai/exports/charts/temp_chart.png.')
        ```
2024-07-30 22:57:35 [INFO] Executing Step 6: CodeExecution
2024-07-30 22:57:35 [ERROR] Failed with error: Traceback (most recent call last):
  File "/home/caio/workspace/genai/.genai/lib/python3.10/site-packages/pandasai/pipelines/chat/code_execution.py", line 85, in execute
    result = self.execute_code(code_to_run, code_context)
  File "/home/caio/workspace/genai/.genai/lib/python3.10/site-packages/pandasai/pipelines/chat/code_execution.py", line 171, in execute_code
    exec(code, environment)
  File "<string>", line 3, in <module>
  File "/home/caio/workspace/genai/.genai/lib/python3.10/site-packages/pandas/core/frame.py", line 664, in __init__
    mgr = dict_to_mgr(data, index, columns, dtype=dtype, copy=copy, typ=manager)
  File "/home/caio/workspace/genai/.genai/lib/python3.10/site-packages/pandas/core/internals/construction.py", line 493, in dict_to_mgr
    return arrays_to_mgr(arrays, columns, index, dtype=dtype, typ=typ, consolidate=copy)
  File "/home/caio/workspace/genai/.genai/lib/python3.10/site-packages/pandas/core/internals/construction.py", line 118, in arrays_to_mgr
    index = _extract_index(arrays)
  File "/home/caio/workspace/genai/.genai/lib/python3.10/site-packages/pandas/core/internals/construction.py", line 656, in _extract_index
    raise ValueError("If using all scalar values, you must pass an index")
ValueError: If using all scalar values, you must pass an index

2024-07-30 22:57:35 [WARNING] Failed to execute code retrying with a correction framework [retry number: 1]
2024-07-30 22:57:35 [INFO] Executing Pipeline: ErrorCorrectionPipeline
2024-07-30 22:57:35 [INFO] Executing Step 0: ErrorPromptGeneration
2024-07-30 22:57:35 [INFO] Using prompt: <dataframe>
dfs[0]:5x3
NUMBER,LETTER,MONTH
4,D,May
1,C,February
5,B,January
</dataframe>


The user asked the following question:
### QUERY
 how many columns are in the dataset?

You generated this python code:
for _, row in df.iterrows():
    new_df = {'NUMBER': str(row[0]), 'LETTER': str(row[1]), 'MONTH': str(row[2])}
    dfs.append(pd.DataFrame(new_df))
result = pd.concat(dfs, ignore_index=True)
print('The dataset has', len(result.columns), 'columns.')


def plot_unique_values(column):
    plt.figure(figsize=(10, 5))
    unique_counts = result[column].unique().shape[0]
    plt.bar(unique_counts * [column], range(unique_counts), color='blue')
    plt.xlabel('Column Name')
    plt.ylabel('Number of Unique Values')
    plt.title(f'{result[column].nunique()}-unique values in column {column}')
    return plt.gcf()


for col_name, df in dfs.items():
    plot_unique_values(col_name)
plt.tight_layout()
plt.show()
print(f'The chart is saved as /home/caio/workspace/genai/exports/charts/temp_chart.png.')

It fails with the following error:
Traceback (most recent call last):
  File "/home/caio/workspace/genai/.genai/lib/python3.10/site-packages/pandasai/pipelines/chat/code_execution.py", line 85, in execute
    result = self.execute_code(code_to_run, code_context)
  File "/home/caio/workspace/genai/.genai/lib/python3.10/site-packages/pandasai/pipelines/chat/code_execution.py", line 171, in execute_code
    exec(code, environment)
  File "<string>", line 3, in <module>
  File "/home/caio/workspace/genai/.genai/lib/python3.10/site-packages/pandas/core/frame.py", line 664, in __init__
    mgr = dict_to_mgr(data, index, columns, dtype=dtype, copy=copy, typ=manager)
  File "/home/caio/workspace/genai/.genai/lib/python3.10/site-packages/pandas/core/internals/construction.py", line 493, in dict_to_mgr
    return arrays_to_mgr(arrays, columns, index, dtype=dtype, typ=typ, consolidate=copy)
  File "/home/caio/workspace/genai/.genai/lib/python3.10/site-packages/pandas/core/internals/construction.py", line 118, in arrays_to_mgr
    index = _extract_index(arrays)
  File "/home/caio/workspace/genai/.genai/lib/python3.10/site-packages/pandas/core/internals/construction.py", line 656, in _extract_index
    raise ValueError("If using all scalar values, you must pass an index")
ValueError: If using all scalar values, you must pass an index


Fix the python code above and return the new python code:
2024-07-30 22:57:35 [INFO] Executing Step 1: CodeGenerator
2024-07-30 22:57:45 [INFO] HTTP Request: POST http://localhost:11434/v1/chat/completions "HTTP/1.1 200 OK"
2024-07-30 22:57:45 [INFO] Prompt used:
            <dataframe>
dfs[0]:5x3
NUMBER,LETTER,MONTH
4,D,May
1,C,February
5,B,January
</dataframe>


The user asked the following question:
### QUERY
 how many columns are in the dataset?

You generated this python code:
for _, row in df.iterrows():
    new_df = {'NUMBER': str(row[0]), 'LETTER': str(row[1]), 'MONTH': str(row[2])}
    dfs.append(pd.DataFrame(new_df))
result = pd.concat(dfs, ignore_index=True)
print('The dataset has', len(result.columns), 'columns.')


def plot_unique_values(column):
    plt.figure(figsize=(10, 5))
    unique_counts = result[column].unique().shape[0]
    plt.bar(unique_counts * [column], range(unique_counts), color='blue')
    plt.xlabel('Column Name')
    plt.ylabel('Number of Unique Values')
    plt.title(f'{result[column].nunique()}-unique values in column {column}')
    return plt.gcf()


for col_name, df in dfs.items():
    plot_unique_values(col_name)
plt.tight_layout()
plt.show()
print(f'The chart is saved as /home/caio/workspace/genai/exports/charts/temp_chart.png.')

It fails with the following error:
Traceback (most recent call last):
  File "/home/caio/workspace/genai/.genai/lib/python3.10/site-packages/pandasai/pipelines/chat/code_execution.py", line 85, in execute
    result = self.execute_code(code_to_run, code_context)
  File "/home/caio/workspace/genai/.genai/lib/python3.10/site-packages/pandasai/pipelines/chat/code_execution.py", line 171, in execute_code
    exec(code, environment)
  File "<string>", line 3, in <module>
  File "/home/caio/workspace/genai/.genai/lib/python3.10/site-packages/pandas/core/frame.py", line 664, in __init__
    mgr = dict_to_mgr(data, index, columns, dtype=dtype, copy=copy, typ=manager)
  File "/home/caio/workspace/genai/.genai/lib/python3.10/site-packages/pandas/core/internals/construction.py", line 493, in dict_to_mgr
    return arrays_to_mgr(arrays, columns, index, dtype=dtype, typ=typ, consolidate=copy)
  File "/home/caio/workspace/genai/.genai/lib/python3.10/site-packages/pandas/core/internals/construction.py", line 118, in arrays_to_mgr
    index = _extract_index(arrays)
  File "/home/caio/workspace/genai/.genai/lib/python3.10/site-packages/pandas/core/internals/construction.py", line 656, in _extract_index
    raise ValueError("If using all scalar values, you must pass an index")
ValueError: If using all scalar values, you must pass an index


Fix the python code above and return the new python code:
            
2024-07-30 22:57:45 [INFO] Code generated:
            ```
            for col_name, df in dfs.items():
    result[col_name] = (result[col_name].astype(str) + "").str.strip() + df["LETTER"].str.replace(' ', '')

print(result.columns)
            ```
            
2024-07-30 22:57:45 [INFO] Executing Step 2: CodeCleaning
2024-07-30 22:57:45 [INFO] 
Code running:
```
for col_name, df in dfs.items():
    result[col_name] = (result[col_name].astype(str) + '').str.strip() + df['LETTER'].str.replace(' ', '')
print(result.columns)
        ```
2024-07-30 22:57:45 [ERROR] Failed with error: Traceback (most recent call last):
  File "/home/caio/workspace/genai/.genai/lib/python3.10/site-packages/pandasai/pipelines/chat/code_execution.py", line 85, in execute
    result = self.execute_code(code_to_run, code_context)
  File "/home/caio/workspace/genai/.genai/lib/python3.10/site-packages/pandasai/pipelines/chat/code_execution.py", line 171, in execute_code
    exec(code, environment)
  File "<string>", line 1, in <module>
AttributeError: 'list' object has no attribute 'items'

2024-07-30 22:57:45 [WARNING] Failed to execute code retrying with a correction framework [retry number: 2]
2024-07-30 22:57:45 [INFO] Executing Pipeline: ErrorCorrectionPipeline
2024-07-30 22:57:45 [INFO] Executing Step 0: ErrorPromptGeneration
2024-07-30 22:57:45 [INFO] Using prompt: <dataframe>
dfs[0]:5x3
NUMBER,LETTER,MONTH
4,D,May
1,C,February
5,B,January
</dataframe>


The user asked the following question:
### QUERY
 how many columns are in the dataset?

You generated this python code:
for col_name, df in dfs.items():
    result[col_name] = (result[col_name].astype(str) + '').str.strip() + df['LETTER'].str.replace(' ', '')
print(result.columns)

It fails with the following error:
Traceback (most recent call last):
  File "/home/caio/workspace/genai/.genai/lib/python3.10/site-packages/pandasai/pipelines/chat/code_execution.py", line 85, in execute
    result = self.execute_code(code_to_run, code_context)
  File "/home/caio/workspace/genai/.genai/lib/python3.10/site-packages/pandasai/pipelines/chat/code_execution.py", line 171, in execute_code
    exec(code, environment)
  File "<string>", line 1, in <module>
AttributeError: 'list' object has no attribute 'items'


Fix the python code above and return the new python code:
2024-07-30 22:57:45 [INFO] Executing Step 1: CodeGenerator
2024-07-30 22:57:56 [INFO] HTTP Request: POST http://localhost:11434/v1/chat/completions "HTTP/1.1 200 OK"
2024-07-30 22:57:56 [INFO] Prompt used:
            <dataframe>
dfs[0]:5x3
NUMBER,LETTER,MONTH
4,D,May
1,C,February
5,B,January
</dataframe>


The user asked the following question:
### QUERY
 how many columns are in the dataset?

You generated this python code:
for col_name, df in dfs.items():
    result[col_name] = (result[col_name].astype(str) + '').str.strip() + df['LETTER'].str.replace(' ', '')
print(result.columns)

It fails with the following error:
Traceback (most recent call last):
  File "/home/caio/workspace/genai/.genai/lib/python3.10/site-packages/pandasai/pipelines/chat/code_execution.py", line 85, in execute
    result = self.execute_code(code_to_run, code_context)
  File "/home/caio/workspace/genai/.genai/lib/python3.10/site-packages/pandasai/pipelines/chat/code_execution.py", line 171, in execute_code
    exec(code, environment)
  File "<string>", line 1, in <module>
AttributeError: 'list' object has no attribute 'items'


Fix the python code above and return the new python code:
            
2024-07-30 22:57:56 [INFO] Code generated:
            ```
            for col_name, df in dfs.items():
    result[col_name] = (result[col_name].astype(str) + '').str.strip() + df['LETTER'].str.replace(' ', '')
    
    result.columns = [col_name]
print(result.columns)
            ```
            
2024-07-30 22:57:56 [INFO] Executing Step 2: CodeCleaning
2024-07-30 22:57:56 [INFO] 
Code running:
```
for col_name, df in dfs.items():
    result[col_name] = (result[col_name].astype(str) + '').str.strip() + df['LETTER'].str.replace(' ', '')
    result.columns = [col_name]
print(result.columns)
        ```
2024-07-30 22:57:56 [ERROR] Failed with error: Traceback (most recent call last):
  File "/home/caio/workspace/genai/.genai/lib/python3.10/site-packages/pandasai/pipelines/chat/code_execution.py", line 85, in execute
    result = self.execute_code(code_to_run, code_context)
  File "/home/caio/workspace/genai/.genai/lib/python3.10/site-packages/pandasai/pipelines/chat/code_execution.py", line 171, in execute_code
    exec(code, environment)
  File "<string>", line 1, in <module>
AttributeError: 'list' object has no attribute 'items'

2024-07-30 22:57:56 [WARNING] Failed to execute code retrying with a correction framework [retry number: 3]
2024-07-30 22:57:56 [INFO] Executing Pipeline: ErrorCorrectionPipeline
2024-07-30 22:57:56 [INFO] Executing Step 0: ErrorPromptGeneration
2024-07-30 22:57:56 [INFO] Using prompt: <dataframe>
dfs[0]:5x3
NUMBER,LETTER,MONTH
4,D,May
1,C,February
5,B,January
</dataframe>


The user asked the following question:
### QUERY
 how many columns are in the dataset?

You generated this python code:
for col_name, df in dfs.items():
    result[col_name] = (result[col_name].astype(str) + '').str.strip() + df['LETTER'].str.replace(' ', '')
    result.columns = [col_name]
print(result.columns)

It fails with the following error:
Traceback (most recent call last):
  File "/home/caio/workspace/genai/.genai/lib/python3.10/site-packages/pandasai/pipelines/chat/code_execution.py", line 85, in execute
    result = self.execute_code(code_to_run, code_context)
  File "/home/caio/workspace/genai/.genai/lib/python3.10/site-packages/pandasai/pipelines/chat/code_execution.py", line 171, in execute_code
    exec(code, environment)
  File "<string>", line 1, in <module>
AttributeError: 'list' object has no attribute 'items'


Fix the python code above and return the new python code:
2024-07-30 22:57:56 [INFO] Executing Step 1: CodeGenerator
2024-07-30 22:58:03 [INFO] HTTP Request: POST http://localhost:11434/v1/chat/completions "HTTP/1.1 200 OK"
2024-07-30 22:58:03 [INFO] Prompt used:
            <dataframe>
dfs[0]:5x3
NUMBER,LETTER,MONTH
4,D,May
1,C,February
5,B,January
</dataframe>


The user asked the following question:
### QUERY
 how many columns are in the dataset?

You generated this python code:
for col_name, df in dfs.items():
    result[col_name] = (result[col_name].astype(str) + '').str.strip() + df['LETTER'].str.replace(' ', '')
    result.columns = [col_name]
print(result.columns)

It fails with the following error:
Traceback (most recent call last):
  File "/home/caio/workspace/genai/.genai/lib/python3.10/site-packages/pandasai/pipelines/chat/code_execution.py", line 85, in execute
    result = self.execute_code(code_to_run, code_context)
  File "/home/caio/workspace/genai/.genai/lib/python3.10/site-packages/pandasai/pipelines/chat/code_execution.py", line 171, in execute_code
    exec(code, environment)
  File "<string>", line 1, in <module>
AttributeError: 'list' object has no attribute 'items'


Fix the python code above and return the new python code:
            
2024-07-30 22:58:03 [INFO] Code generated:
            ```
            for col_name, df in dfs.items():
    result[col_name] = (result[col_name].astype(str) + '').str.strip() + df['LETTER'].str.replace(' ', '')
    result.columns = [col_name]
print(result)
            ```
            
2024-07-30 22:58:03 [INFO] Executing Step 2: CodeCleaning
2024-07-30 22:58:03 [INFO] 
Code running:
```
for col_name, df in dfs.items():
    result[col_name] = (result[col_name].astype(str) + '').str.strip() + df['LETTER'].str.replace(' ', '')
    result.columns = [col_name]
print(result)
        ```
2024-07-30 22:58:03 [ERROR] Failed with error: Traceback (most recent call last):
  File "/home/caio/workspace/genai/.genai/lib/python3.10/site-packages/pandasai/pipelines/chat/code_execution.py", line 85, in execute
    result = self.execute_code(code_to_run, code_context)
  File "/home/caio/workspace/genai/.genai/lib/python3.10/site-packages/pandasai/pipelines/chat/code_execution.py", line 171, in execute_code
    exec(code, environment)
  File "<string>", line 1, in <module>
AttributeError: 'list' object has no attribute 'items'

2024-07-30 22:58:03 [ERROR] Pipeline failed on step 6: 'list' object has no attribute 'items'
